<?xml version="1.0"?>
<robot name="bras_robotique" xmlns:xacro="http://www.ros.org/wiki/xacro">
  <xacro:property name="PI" value="3.14159265359"/>
  <xacro:property name="description_package" value="modelisation_bras_robotique"/>
  <xacro:property name="mesh_scale" value="0.01 0.01 0.01"/>

  <xacro:include filename="$(find modelisation_bras_robotique)/urdf/materials.xacro"/>
  <xacro:include filename="$(find modelisation_bras_robotique)/urdf/inertials.xacro"/>
  <xacro:include filename="$(find modelisation_bras_robotique)/urdf/arm_macro.xacro"/>

  <link name="world"/>

  <link name="base_link">
    <xacro:mesh_visual mesh="basement.STL" material="industrial_dark" xyz="-0.5 -0.5 0" rpy="0 0 0"/>
    <xacro:cylinder_collision xyz="0 0 0.15" rpy="0 0 0" radius="0.6" length="0.3"/>
    <xacro:box_link_inertial mass="1.0" x="1.2" y="1.2" z="0.3" xyz="0 0 0.15"/>
  </link>

  <joint name="virtual_joint" type="fixed">
    <parent link="world"/>
    <child link="base_link"/>
    <origin xyz="0 0 0" rpy="0 0 0"/>
  </joint>

  <link name="base_plate">
    <xacro:mesh_visual mesh="base_plate.STL" material="industrial_silver" xyz="-0.39 -0.39 -0.56" rpy="0 0 0"/>
    <xacro:cylinder_collision xyz="0 0 0.175" rpy="0 0 0" radius="0.5" length="0.35"/>
    <xacro:box_link_inertial mass="0.8" x="1.0" y="1.0" z="0.35" xyz="0 0 0.175"/>
  </link>

  <joint name="joint1" type="revolute">
    <parent link="base_link"/>
    <child link="base_plate"/>
    <!-- Repere base_link/base_plate : ecart vertical de 3.07 cm mesure sur le schema -> Z=0.0307. Multiplie par 10 pour correspondre a l'echelle visuelle de 0.01 -> Z=0.307. -->
    <origin xyz="0 0 0.307" rpy="0 0 0"/>
    <axis xyz="0 0 1"/>
    <limit lower="-3.14" upper="3.14" effort="30.0" velocity="2.0"/>
  </joint>

  <link name="forward_drive_arm">
    <xacro:mesh_visual mesh="forward_drive_arm.STL" material="industrial_blue" xyz="0.19 0.06 -0.08" rpy="0 -${PI/2} ${PI/2}"/>
    <xacro:box_collision xyz="0 0 0.4" rpy="0 0 0" size="0.4 0.4 0.8"/>
    <xacro:box_link_inertial mass="0.6" x="0.4" y="0.4" z="0.8" xyz="0 0 0.4"/>
  </link>

  <joint name="joint2" type="revolute">
    <parent link="base_plate"/>
    <child link="forward_drive_arm"/>
    <origin xyz="-0.018 0.03 0.36" rpy="0 0 0"/>
    <axis xyz="1 0 0"/>
    <limit lower="-1.57" upper="1.57" effort="25.0" velocity="2.0"/>
  </joint>

  <link name="horizontal_arm">
    <xacro:mesh_visual mesh="horizontal_arm.STL" material="industrial_yellow" xyz="-0.03 -0.4 -0.06" rpy="${PI/2} 0 ${PI/2}"/>
    <xacro:box_collision xyz="0 0.41 0" rpy="0 0 0" size="0.3 0.82 0.3"/>
    <xacro:box_link_inertial mass="0.5" x="0.3" y="0.82" z="0.3" xyz="0 0.41 0"/>
  </link>

  <joint name="joint3" type="revolute">
    <parent link="forward_drive_arm"/>
    <child link="horizontal_arm"/>
    <!-- Repere forward_drive_arm/horizontal_arm : ecart vertical de 8 cm -> Z=0.08. Multiplie par 10 -> Z=0.8. -->
    <origin xyz="0 -0.02 0.78" rpy="0 0 0"/>
    <axis xyz="1 0 0"/>
    <limit lower="-1.57" upper="1.57" effort="20.0" velocity="2.0"/>
  </joint>

  <link name="claw_support">
    <xacro:mesh_visual mesh="claw_support.STL" material="industrial_silver" xyz="0 -0.05 -0.15" rpy="0 0 ${PI/2}"/>
    <xacro:box_collision xyz="0 0 -0.1" rpy="0 0 0" size="0.4 0.4 0.3"/>
    <xacro:box_link_inertial mass="0.25" x="0.4" y="0.4" z="0.3" xyz="0 0 -0.1"/>
  </link>

  <joint name="joint_claw" type="fixed">
    <parent link="horizontal_arm"/>
    <child link="claw_support"/>
    <!-- Repere horizontal_arm/claw_support : longueur d'avant-bras de 8.2 cm -> Y=0.082. Multiplie par 10 -> Y=0.82. -->
    <origin xyz="0.135 0.82 0.02" rpy="0 0 0"/>
  </joint>

  <link name="gripper_right">
    <xacro:mesh_visual mesh="right_finger.STL" material="gripper_gray" xyz="-0.1 0.5 -0.1" rpy="0 0 -${PI/2}"/>
    <xacro:box_collision xyz="0 0.15 -0.05" rpy="0 0 0" size="0.15 0.3 0.1"/>
    <xacro:box_link_inertial mass="0.1" x="0.15" y="0.3" z="0.1" xyz="0 0.15 -0.05"/>
  </link>

  <joint name="joint4" type="revolute">
    <parent link="claw_support"/>
    <child link="gripper_right"/>
    <!-- Repere claw_support/gripper_right : apres rotation PI/2 du claw_support,
         la profondeur du mesh (STL Y=25mm) est sur l'axe link_X (negatif : -0.251 a -0.001).
         Le centre en X est a -0.126. Les pivots sont separes de 2.2cm (0.22) selon X.
         Pivot droit : X = -0.126 + 0.11 = -0.016. Z = -0.1 (1cm sous le support, x10). -->
    <origin xyz="-0.02 0 -0.1" rpy="0 0 0"/>
    <axis xyz="0 0 1"/>
    <limit lower="-0.5" upper="0.0" effort="10.0" velocity="2.0"/>
  </joint>

  <link name="gripper_left">
    <xacro:mesh_visual mesh="left_finger.STL" material="gripper_gray" xyz="-0.04 0.5 -0.1" rpy="0 0 -${PI/2}"/>
    <xacro:box_collision xyz="0 0.15 -0.05" rpy="0 0 0" size="0.15 0.3 0.1"/>
    <xacro:box_link_inertial mass="0.1" x="0.15" y="0.3" z="0.1" xyz="0 0.15 -0.05"/>
  </link>

  <joint name="joint5" type="revolute">
    <parent link="claw_support"/>
    <child link="gripper_left"/>
    <!-- Repere claw_support/gripper_left : symetrique de joint4 selon l'axe X.
         Pivot gauche : X = -0.126 - 0.11 = -0.236. Meme Y=0 et Z=-0.1. -->
    <origin xyz="-0.24 0 -0.1" rpy="0 0 0"/>
    <axis xyz="0 0 1"/>
    <limit lower="0.0" upper="0.5" effort="10.0" velocity="2.0"/>
    <mimic joint="joint4" multiplier="-1"/>
  </joint>
</robot>
